Workbook

Sheet Backlog
A1: Poradie | B1: Typ | C1: Názov | D1: Popis | E1: Akceptačné kritériá | F1: Tagy | G1: Activity | H1: Odhad (h)
A2: 1 | B2: Epic | C2: KUKA FM Middleware | D2: Middleware medzi externým systémom / operátorom a KUKA AMR Fleet Manager: zadanie a zrušenie misie, synchronizácia stavov misií a robotov, webové UI, nasadenie cez CI/CD. | E2: • Je možné zadať novú misiu. • Je možné zrušiť prebiehajúcu misiu. • Je možné prezrieť stav prebiehajúcich misií, ktoré sa aktualizujú v reálnom čase, a ukončených misií. • Je možné prezrieť stav robotov, ktoré sa aktualizujú v reálnom čase. • Prístup ku KUKA FM API volaniu je zabezpečený access tokenom. • Všetky operácie vykonané používateľom sú logované. • Proces testovania a nasadenia je plne automatizovaný využitím CI/CD pipeline. | H2: =H3+H22+H27+H38
A3: 1.1 | B3: Feature | C3: Správa misií | D3: Zadanie, zrušenie a prehľad misií vrátane histórie stavov (UC1–UC4, wiki 3.1). | E3: • Misie sa dajú zadať, zrušiť a sledovať cez middleware bez použitia UI KUKA FM. • Každá misia má aktuálny stav aj celú históriu zmien. | F3: FR1; FR2; FR5; FR6 | H3: =H4+H9+H14+H18
A4: 1.1.1 | B4: User Story | C4: UC1 – Zadať misiu | D4: Ako operátor / externý systém chcem zadať novú misiu robotovi, aby ju KUKA FM vykonal. | E4: • Formulár / POST /api/missions prijme typ misie, cieľové body a voliteľne robota. • Neplatný vstup vráti 400, neautorizovaný request 401; KUKA FM sa nevolá. • Po úspešnom submitMission je misia uložená so stavom Created/Submitted, má prvý záznam v histórii a aktér dostane jej ID. • Ak KUKA FM misiu odmietne alebo je nedostupné, misia je Failed, chyba sa zaloguje a API vráti 502. | F4: UC1 | H4: =SUM(H5:H8)
A5: 1.1.1.1 | B5: Task | C5: [BE] Endpoint POST /api/missions + validácia vstupu | D5: Validácia typu misie, cieľových bodov a existencie robota (ak je zadaný). Odpoveď 201 s ID misie alebo 400. | F5: BE | G5: Development | H5: 4
A6: 1.1.1.2 | B6: Task | C6: [BE] Volanie submitMission + uloženie misie a histórie | D6: Vygenerovať MissionCode, uložiť Mission + MissionStep (Created), zavolať submitMission, nastaviť Submitted alebo Failed (ErrorMessage) a zapísať MissionStatusHistory (diagram 4.1). | F6: BE | G6: Development | H6: 5
A7: 1.1.1.3 | B7: Task | C7: [FE] Obrazovka Nová misia (mockup 6.2) | D7: Formulár: typ, cieľové body, voliteľne robot z GET /api/robots. Zobrazenie ID misie alebo chybového hlásenia. | F7: FE | G7: Development | H7: 6
A8: 1.1.1.4 | B8: Task | C8: [TEST] Unit testy zadania misie | D8: Validácia, mapovanie na submitMission request, úspech aj chyba KUKA FM (klient a DB mockované). | F8: TEST | G8: Testing | H8: 4
A9: 1.1.2 | B9: User Story | C9: UC2 – Zrušiť misiu | D9: Ako operátor / externý systém chcem zrušiť rozbehnutú misiu. | E9: • Zrušiť je možné len misiu, ktorá nie je ukončená; v UI vyžaduje potvrdenie. • Neexistujúca misia vráti 404, ukončená 409. • Po úspešnom cancelMission je misia v stave Cancelling a zmena je v histórii. • Finálny stav Cancelled potvrdí synchronizácia (UC5). | F9: UC2 | H9: =SUM(H10:H13)
A10: 1.1.2.1 | B10: Task | C10: [BE] Endpoint POST /api/missions/{id}/cancel + kontroly 404/409 | D10: Načítať misiu, overiť že existuje a nie je ukončená. | F10: BE | G10: Development | H10: 3
A11: 1.1.2.2 | B11: Task | C11: [BE] Volanie cancelMission + stav Cancelling | D11: Zavolať cancelMission na KUKA FM, nastaviť Cancelling a zapísať históriu (diagram 4.2). | F11: BE | G11: Development | H11: 3
A12: 1.1.2.3 | B12: Task | C12: [FE] Tlačidlo Zrušiť s potvrdením (mockup 6.4) | D12: Tlačidlo len pri aktívnych misiách, potvrdzovací dialóg, zobrazenie výsledku. | F12: FE | G12: Development | H12: 3
A13: 1.1.2.4 | B13: Task | C13: [TEST] Unit testy zrušenia misie | D13: Prípady: aktívna, ukončená (409), neexistujúca (404). | F13: TEST | G13: Testing | H13: 3
A14: 1.1.3 | B14: User Story | C14: UC3 – Zobraziť zoznam misií | D14: Ako operátor / externý systém chcem vidieť prebiehajúce aj ukončené misie s aktuálnym stavom. | E14: • Zoznam zobrazuje misie s aktuálnym stavom, voliteľne filter aktívne / ukončené. • Dáta sa čítajú len z vlastnej DB, KUKA FM sa nevolá. • UI sa priebežne obnovuje (real-time aktualizácia). | F14: UC3 | H14: =SUM(H15:H17)
A15: 1.1.3.1 | B15: Task | C15: [BE] Endpoint GET /api/missions?state=active|finished | D15: Čítanie z DB (diagram 4.3), zoradenie podľa CreatedAt desc. | F15: BE | G15: Development | H15: 3
A16: 1.1.3.2 | B16: Task | C16: [FE] Obrazovka Zoznam misií + filter + auto-refresh (mockup 6.1) | D16: Tabuľka misií so stavom, filter aktívne / ukončené, periodické obnovovanie. | F16: FE | G16: Development | H16: 6
A17: 1.1.3.3 | B17: Task | C17: [TEST] Unit testy filtra aktívne / ukončené | F17: TEST | G17: Testing | H17: 2
A18: 1.1.4 | B18: User Story | C18: UC4 – Zobraziť históriu stavov misie | D18: Ako operátor chcem vidieť časovú os zmien stavu konkrétnej misie. | E18: • Z detailu misie je vidieť všetky záznamy histórie stavov zoradené podľa času. • Neexistujúca misia vráti 404. | F18: UC4 | H18: =SUM(H19:H21)
A19: 1.1.4.1 | B19: Task | C19: [BE] Endpointy GET /api/missions/{id} a /api/missions/{id}/history | D19: Detail misie s MissionStep a záznamy MissionStatusHistory zoradené podľa ChangedAt. | F19: BE | G19: Development | H19: 3
A20: 1.1.4.2 | B20: Task | C20: [FE] Obrazovka Detail misie s časovou osou (mockup 6.3) | F20: FE | G20: Development | H20: 5
A21: 1.1.4.3 | B21: Task | C21: [TEST] Unit testy histórie (poradie, 404) | F21: TEST | G21: Testing | H21: 2
A22: 1.2 | B22: Feature | C22: Prehľad robotov | D22: Zoznam robotov a ich aktuálneho stavu (UC6, wiki 3.2). | E22: • UI zobrazuje všetky roboty so stavom Dostupný / Zaneprázdnený / Offline. | F22: FR7 | H22: =H23
A23: 1.2.1 | B23: User Story | C23: UC6 – Zobraziť zoznam robotov | D23: Ako operátor chcem vidieť roboty a ich aktuálny stav. | E23: • Zoznam zobrazuje roboty a ich stav (dostupný / zaneprázdnený / offline). • Dáta sa čítajú len z vlastnej DB a UI sa priebežne obnovuje. | F23: UC6 | H23: =SUM(H24:H26)
A24: 1.2.1.1 | B24: Task | C24: [BE] Endpoint GET /api/robots | F24: BE | G24: Development | H24: 2
A25: 1.2.1.2 | B25: Task | C25: [FE] Obrazovka Roboty + auto-refresh (mockup 6.5) | F25: FE | G25: Development | H25: 5
A26: 1.2.1.3 | B26: Task | C26: [TEST] Unit testy endpointu robotov | F26: TEST | G26: Testing | H26: 2
A27: 1.3 | B27: Feature | C27: Synchronizácia s KUKA FM | D27: Prístup ku KUKA FM s tokenom a periodická synchronizácia stavov misií a robotov (UC5, UC7, wiki 3.3 a 4.0). | E27: • Stavy misií a robotov v DB sú aktuálne bez zásahu používateľa. • Každé volanie na KUKA FM obsahuje platný access token. | F27: FR3; FR4; FR5; NFR3 | H27: =H28+H32+H35
A28: 1.3.1 | B28: User Story | C28: Prístup ku KUKA FM API s access tokenom | D28: Ako middleware potrebujem pri každom volaní na KUKA FM platný token (diagram 4.0). | E28: • Všetky volania (submitMission, cancelMission, Query jobs, query robotov) idú cez jedného klienta. • Pred volaním sa overí token v cache; ak nie je platný, vydá sa nový a uloží do cache. • Každé volanie má hlavičku Authorization. • Pri odpovedi 401 sa token zneplatní a obnoví najviac raz. • Úspešné aj neúspešné volania a chyba autentifikácie sa zalogujú. | F28: NFR3 | H28: =SUM(H29:H31)
A29: 1.3.1.1 | B29: Task | C29: [BE] Typovaný klient KUKA FM (submitMission, cancelMission, Query jobs, query robotov) | D29: URL a prístupové údaje z konfigurácie, logovanie každého volania. | F29: BE | G29: Development | H29: 5
A30: 1.3.1.2 | B30: Task | C30: [BE] Token – vydanie, cache, hlavička Authorization, obnova pri 401 | D30: Podľa diagramu 4.0. | F30: BE | G30: Development | H30: 4
A31: 1.3.1.3 | B31: Task | C31: [TEST] Unit testy klienta a tokenu | D31: Platný token v cache, vydanie nového, 401 + obnova, opakovaná 401, chyba autentifikácie. | F31: TEST | G31: Testing | H31: 3
A32: 1.3.2 | B32: User Story | C32: UC7 – Synchronizovať stav robotov | D32: Ako plánovač chcem periodicky načítať stav robotov z KUKA FM. | E32: • Plánovač v intervale zavolá query API robotov na KUKA FM. • Stav KUKA FM sa namapuje na dostupný / zaneprázdnený / offline. • Nové roboty sa vložia, existujúcim sa aktualizuje stav a LastSeenAt. • Pri neúspešnom volaní sa chyba zaloguje a dáta sa nemenia. | F32: UC7 | H32: =SUM(H33:H34)
A33: 1.3.2.1 | B33: Task | C33: [BE] Background služba – query robotov, mapovanie stavov, vloženie / aktualizácia | D33: Podľa diagramu 4.5. | F33: BE | G33: Development | H33: 5
A34: 1.3.2.2 | B34: Task | C34: [TEST] Unit testy synchronizácie robotov | D34: Nový robot, zmena stavu, bez zmeny, výpadok KUKA FM. | F34: TEST | G34: Testing | H34: 3
A35: 1.3.3 | B35: User Story | C35: UC5 – Synchronizovať stav misií | D35: Ako plánovač chcem periodicky aktualizovať stav aktívnych misií z KUKA FM. | E35: • Plánovač v intervale (napr. 5 s) načíta aktívne misie (Submitted, InProgress, Cancelling) a zavolá Query jobs API. • Pri zmene stavu sa aktualizuje Mission.Status a pridá sa záznam do histórie. • Koncový stav (Completed, Cancelled, Failed) nastaví FinishedAt. • Každej spracovanej misii sa nastaví LastSyncedAt a zmeny sa uložia v transakcii. • Ak je KUKA FM nedostupné, chyba sa zaloguje a ďalší pokus prebehne v nasledujúcom cykle. | F35: UC5 | H35: =SUM(H36:H37)
A36: 1.3.3.1 | B36: Task | C36: [BE] Background služba – Query jobs, porovnanie stavov, zápis histórie | D36: Podľa diagramu 4.4. | F36: BE | G36: Development | H36: 6
A37: 1.3.3.2 | B37: Task | C37: [TEST] Unit testy synchronizácie misií | D37: Zmena stavu, koncový stav, bez zmeny, výpadok KUKA FM. | F37: TEST | G37: Testing | H37: 3
A38: 1.4 | B38: Feature | C38: Nasadenie a prevádzka | D38: Kontajnerizácia, databáza, zabezpečenie API, logovanie a CI/CD. | E38: • Aplikácia beží v Dockeri a je zbuildovaná, otestovaná a nasadená pipeline bez ručných krokov. | F38: NFR1; NFR2; NFR4; NFR5 | H38: =H39+H44+H49+H53
A39: 1.4.1 | B39: User Story | C39: Kontajnerizácia a databáza | D39: Ako tím chceme spustiť celé riešenie jedným príkazom s perzistentnou DB. | E39: • docker compose up spustí web, api a PostgreSQL. • Schéma DB zodpovedá ERD (wiki 5) a vzniká EF Core migráciou pri štarte API. • Dáta prežijú reštart kontajnerov. | F39: NFR1 | H39: =SUM(H40:H43)
A40: 1.4.1.1 | B40: Task | C40: [BE] Kostra .NET riešenia + EF Core DbContext a migrácia podľa ERD | F40: BE | G40: Development | H40: 5
...

Sheet Súhrn
A1: Backlog – súhrn odhadov
A3: Feature | B3: Odhad (h)
A4: Správa misií | B4: =Backlog!H3
A5: Prehľad robotov | B5: =Backlog!H22
A6: Synchronizácia s KUKA FM | B6: =Backlog!H27
A7: Nasadenie a prevádzka | B7: =Backlog!H38
A8: Spolu | B8: =SUM(B4:B7)
A10: Activity | B10: Odhad (h)
A11: Development | B11: =SUMIFS(Backlog!H2:H56,Backlog!B2:B56,"Task",Backlog!G2:G56,A11)
A12: Testing | B12: =SUMIFS(Backlog!H2:H56,Backlog!B2:B56,"Task",Backlog!G2:G56,A12)
A13: Deployment | B13: =SUMIFS(Backlog!H2:H56,Backlog!B2:B56,"Task",Backlog!G2:G56,A13)
A14: Spolu | B14: =SUM(B11:B13)
A16: Počet položiek
A17: Feature | B17: =COUNTIF(Backlog!B2:B56,"Feature")
A18: User Story | B18: =COUNTIF(Backlog!B2:B56,"User Story")
A19: Task | B19: =COUNTIF(Backlog!B2:B56,"Task")
